Workbook

Sheet Items Tela
A1: Item Mattelsa | B1: Item URA | C1: Descripcion
A2: 5306 | B2: 320 | C2: JERSEY ELASTANO - BAHAMAS
A3: 5375 | B3: 321 | C3: SINTETICO - DUNGA SEC
A4: 5576 | B4: 322 | C4: JERSEY 24/1 ESMERILADO - SANTORINI/CLARO
A5: 7961 | B5: 323 | C5: CHALIS - SEDUCTION
A6: 7965 | B6: 324 | C6: SINTETICO - LA MEGA
A7: 8078 | B7: 325 | C7: JERSEY 36/1 - BAILARINA
A8: 8624 | B8: 326 | C8: JERSEY 30/1 DONCELLA
A9: 8625 | B9: 327 | C9: RIB 30/1 DONCELLA
A10: 9510 | B10: 328 | C10: BURDA MALASIA
A11: 10450 | B11: 329 | C11: JERSEY 40/1 - ORCA
A12: 12926 | B12: 330 | C12: JERSEY VISCOSA ELASTANO - GALAXIA
A13: 14413 | B13: 331 | C13: BURDA - GIBRALTAR 3J595 TOUCH 303R73
... A245: 96664 | B245: 535 | C245: SINTETICO - ROBIN
A246: BURDA - TSUNAMI T11782 | B246: 4054 | C246: BURDA - TSUNAMI T11782
A247: FORRO - TEJIDO JACQUARD ROSAS CLEMONT | B247: 152 | C247: FORRO - TEJIDO JACQUARD ROSAS CLEMONT
A248: JERSEY - GALLETA | B248: 4056 | C248: JERSEY - GALLETA
A249: JERSEY - POLONIA | B249: 4095 | C249: JERSEY - POLONIA
A250: RIB 1X1 - POLONIA | B250: 4096 | C250: RIB 1X1 - POLONIA
A251: RIB 1X1 - TSUNAMI T11783 | B251: 4055 | C251: RIB 1X1 - TSUNAMI T11783

Sheet Extensiones Telas
A1: Codigo Ext Matt | B1: Descripcion Extension | C1: Codigo Ext URA
A2: 16 | B2: BPT/APT | C2: 3
A3: 5964 | B3: NEGRO E349AQ-NEGRO 3 | C3: 4
A4: 6076 | B4: AZUL 19-4053 TPG Z329XD OP-3 | C4: 5
A5: 6320 | B5: VERDE S/M PONDEROSA V34342-03 | C5: 6
A6: 6411 | B6: CREMA NEW 0915R SM A319YK-03 | C6: 7
A7: 6488 | B7: VERDE PINO S/M 63301441-2 | C7: 8
A8: 6494 | B8: CREMA TH A319VK-3 | C8: 9
A9: 6570 | B9: NEGRO PROFUNDO SM E349H8-02 | C9: 10
A10: 6602 | B10: MARFIL MARSHMALLOW 11-4300 TPG A31741 TH | C10: 11
A11: 6642 | B11: TOFU TH A319E1-01 | C11: 12
A12: 6645 | B12: MARSHMELLOW TH A31741 | C12: 13
A13: 6681 | B13: CEREZA R32A69-03 TPG 19-1652 | C13: 14
... A373: 358 | B373: CAMEL 44 | C373: 374

Sheet Item-Extensiones Telas
A1: Item-Ext Matt | B1: Item-Ext URA
A2: 35845-6682 | B2: 288-15
A3: 35845-16 | B3: 288-3
A4: 35845-6570 | B4: 288-10
A5: 59420-6682 | B5: 289-15
A6: 59420-6570 | B6: 289-10
A7: 77672-6411 | B7: 290-7
A8: 77673-6570 | B8: 291-10
A9: 77673-6411 | B9: 291-7
A10: 77673-16 | B10: 291-3
A11: 78107-6494 | B11: 292-9
A12: 78130-6494 | B12: 293-9
... A1032: 96664-10 | B1032: 535-246

Sheet Lotes Telas
A1: Lote Matt | B1: A | C1: Lote Ura | D1: Item Matt | E1: Extension Matt | F1: Item URA | G1: Ext URA | H1: Lote Proveedor Matt
A2: 000001 | B2: 1 | C2: 000001 | D2: 81946 | E2: 5965 | F2: 298 | G2: 20
A3: 000002 | B3: 2 | C3: 000002 | D3: 81946 | E3: 5965 | F3: 298 | G3: 20
A4: 000003 | B4: 3 | C4: 000003 | D4: 81946 | E4: 5965 | F4: 298 | G4: 20
A5: 000004 | B5: 4 | C5: 000004 | D5: 81946 | E5: 5965 | F5: 298 | G5: 20
A6: 000005 | B6: 5 | C6: 000005 | D6: 81946 | E6: 5965 | F6: 298 | G6: 20
A7: 000006 | B7: 6 | C7: 000006 | D7: 81946 | E7: 5965 | F7: 298 | G7: 20
A8: 000007 | B8: 7 | C8: 000007 | D8: 81946 | E8: 5965 | F8: 298 | G8: 20
A9: 000008 | B9: 8 | C9: 000008 | D9: 81946 | E9: 5965 | F9: 298 | G9: 20
A10: 000009 | B10: 9 | C10: 000009 | D10: 81946 | E10: 5965 | F10: 298 | G10: 20
A11: 000010 | B11: 10 | C11: 000010 | D11: 81946 | E11: 5965 | F11: 298 | G11: 20
A12: 000011 | B12: 11 | C12: 000011 | D12: 81946 | E12: 5965 | F12: 298 | G12: 20
A13: 000012 | B13: 12 | C13: 000012 | D13: 81946 | E13: 5965 | F13: 298 | G13: 20
... A115: 000114 | B115: 114 | C115: 000114 | D115: 81946 | E115: 6488 | F115: 298 | G115: 8
A116: 000115 | B116: 115 | C116: 000115 | D116: 93030 | E116: 6494 | F116: 308 | G116: 9 | H116: 6660
A117: 000116 | B117: 116 | C117: 000116 | D117: 93030 | E117: 6494 | F117: 308 | G117: 9 | H117: 6661
A118: 000117 | B118: 117 | C118: 000117 | D118: 93029 | E118: 6494 | F118: 307 | G118: 9 | H118: 6662
A119: 000118 | B119: 118 | C119: 000118 | D119: 93029 | E119: 6494 | F119: 307 | G119: 9 | H119: 6663
A120: 000119 | B120: 119 | C120: 000119 | D120: 93029 | E120: 6494 | F120: 307 | G120: 9 | H120: 6664
A121: 000120 | B121: 120 | C121: 000120 | D121: 93029 | E121: 6494 | F121: 307 | G121: 9 | H121: 6665
A122: 000121 | B122: 121 | C122: 000121 | D122: 93029 | E122: 6494 | F122: 307 | G122: 9 | H122: 6666
A123: 000122 | B123: 122 | C123: 000122 | D123: 93029 | E123: 6494 | F123: 307 | G123: 9 | H123: 6667
A124: 000123 | B124: 123 | C124: 000123 | D124: 93029 | E124: 6494 | F124: 307 | G124: 9 | H124: 6668
A125: 000124 | B125: 124 | C125: 000124 | D125: 93029 | E125: 6494 | F125: 307 | G125: 9 | H125: 6669
A126: 000125 | B126: 125 | C126: 000125 | D126: 93029 | E126: 6494 | F126: 307 | G126: 9 | H126: 6670
A127: 000126 | B127: 126 | C127: 000126 | D127: 93029 | E127: 6494 | F127: 307 | G127: 9 | H127: 6671
... A159: 000158 | B159: 158 | C159: 000158 | D159: 93029 | E159: 6494 | F159: 307 | G159: 9 | H159: 8173
A160: 000159 | B160: 159 | C160: 000159 | D160: 93029 | E160: 6494 | F160: 307 | G160: 9
A161: 000160 | B161: 160 | C161: 000160 | D161: 93029 | E161: 6494 | F161: 307 | G161: 9
A162: 000161 | B162: 161 | C162: 000161 | D162: 93029 | E162: 6494 | F162: 307 | G162: 9
A163: 000162 | B163: 162 | C163: 000162 | D163: 93029 | E163: 6494 | F163: 307 | G163: 9
A164: 000163 | B164: 163 | C164: 000163 | D164: 93029 | E164: 6494 | F164: 307 | G164: 9
A165: 000164 | B165: 164 | C165: 000164 | D165: 93029 | E165: 6494 | F165: 307 | G165: 9
A166: 000165 | B166: 165 | C166: 000165 | D166: 93029 | E166: 6494 | F166: 307 | G166: 9
A167: 000166 | B167: 166 | C167: 000166 | D167: 93029 | E167: 6494 | F167: 307 | G167: 9
A168: 000167 | B168: 167 | C168: 000167 | D168: 93029 | E168: 6494 | F168: 307 | G168: 9
A169: 000168 | B169: 168 | C169: 000168 | D169: 93029 | E169: 6494 | F169: 307 | G169: 9
A170: 000169 | B170: 169 | C170: 000169 | D170: 93029 | E170: 6494 | F170: 307 | G170: 9
A171: 000170 | B171: 170 | C171: 000170 | D171: 93029 | E171: 6494 | F171: 307 | G171: 9
A172: 000171 | B172: 171 | C172: 000171 | D172: 93142 | E172: 6684 | F172: 309 | G172: 17 | H172: 3403
...

Sheet Items Insumos
A1: Item Mattelsa | B1: Item URA | C1: Descripcion
A2: MARQUILLA MARCA COGOT MARQ002 | B2: 21 | C2: MARQUILLA MARCA COGOT MARQ002
A3: MARQUILLA MARCA TALLA S MARQ042 | B3: 25 | C3: MARQUILLA MARCA TALLA S MARQ042
A4: MARQUILLA MARCA TALLA M MARQ045 | B4: 27 | C4: MARQUILLA MARCA TALLA M MARQ045
A5: MARQUILLA MARCA TALLA L MARQ046 | B5: 28 | C5: MARQUILLA MARCA TALLA L MARQ046
A6: MARQUILLA MARCA TALLA XL MARQ047 | B6: 29 | C6: MARQUILLA MARCA TALLA XL MARQ047
A7: MARQUILLA MARCA TALLA XXL MARQ048 | B7: 30 | C7: MARQUILLA MARCA TALLA XXL MARQ048
A8: MARQUILLA BANDERA MRQ004 | B8: 31 | C8: MARQUILLA BANDERA MRQ004
A9: HANGTAG PREMIUM CORDON ENCERADO BEIGE | B9: 32 | C9: HANGTAG PREMIUM CORDON ENCERADO BEIGE
A10: BOLSA BOL013 | B10: 33 | C10: BOLSA BOL013
A11: INST.LAV ROWAN T-SHIRT MEN BLACK S/CH COL | B11: 34 | C11: INST.LAV ROWAN T-SHIRT MEN BLACK S/CH CO
A12: INST.LAV ROWAN T-SHIRT MEN BLACK M/M COL | B12: 35 | C12: INST.LAV ROWAN T-SHIRT MEN BLACK M/M COL
A13: INST.LAV ROWAN T-SHIRT MEN BLACK L/G COL | B13: 36 | C13: INST.LAV ROWAN T-SHIRT MEN BLACK L/G COL
... A91: GARRA MQJ347 CLEMONT 100X60 HYM725 NNO FRITZ NEGRO | B91: 114 | C91: GARRA MQJ347 CLEMONT 100X60 HYM725 NNO F
A92: 93071 | B92: 115 | C92: BANDERIN PVC ROJO GOTICA BAND001
A93: BANDERIN BANDERA PVC GRANDE ROJO | B93: 116 | C93: BANDERIN BANDERA PVC GRANDE ROJO
A94: MARQUILLA MARCA/TALLA 4 TALL007 | B94: 117 | C94: MARQUILLA MARCA/TALLA 4 TALL007
A95: MARQUILLA MARCA/TALLA 6 TALL008 | B95: 118 | C95: MARQUILLA MARCA/TALLA 6 TALL008
A96: MARQUILLA MARCA/TALLA 8 TALL009 | B96: 119 | C96: MARQUILLA MARCA/TALLA 8 TALL009
A97: MARQUILLA MARCA/TALLA 10 TALL010 | B97: 120 | C97: MARQUILLA MARCA/TALLA 10 TALL010
A98: 93017 | B98: 121 | C98: ETIQUETA PRESENTACION 2 SELLO PRESTIGIO
A99: 93011 | B99: 122 | C99: MARQUILLA MARCA PEQUEÑA MARQ001
A100: MARQUILLA TALLA XS TALL001 | B100: 123 | C100: MARQUILLA TALLA XS TALL001
A101: 93012 | B101: 124 | C101: MARQUILLA TALLA S TALL002
A102: 93013 | B102: 125 | C102: MARQUILLA TALLA M TALL003
A103: 93014 | B103: 126 | C103: MARQUILLA TALLA L TALL004
A104: 93015 | B104: 127 | C104: MARQUILLA TALLA XL TALL005
A105: 94414 | B105: 128 | C105: MARQUILLA TALLA XXL TALL006
A106: 94462 | B106: 129 | C106: MARQUILLA MARCA/TALLA 30 TALL011
A107: MARQUILLA MARCA/TALLA 32 TALL012 | B107: 130 | C107: MARQUILLA MARCA/TALLA 32 TALL012
A108: MARQUILLA MARCA/TALLA 34 TALL013 | B108: 131 | C108: MARQUILLA MARCA/TALLA 34 TALL013
A109: MARQUILLA MARCA/TALLA 36 TALL014 | B109: 132 | C109: MARQUILLA MARCA/TALLA 36 TALL014
A110: 94365 | B110: 133 | C110: BOLSA DE EMPAQUE 30CM*40CM BOLS002
A111: 93018 | B111: 139 | C111: BANDERA NYLON ROJA BAND003
A112: BANDERIN BANDERA PVC CLEMONT FL0001 | B112: 140 | C112: BANDERIN BANDERA PVC CLEMONT FL0001
A113: 94467 | B113: 141 | C113: BANDERIN APLIQUE PVC NEGRO CLEMONT
A114: CINTA TIPO RAZO TEJIDA 5CM CONTRAMARCADA CLEMONT | B114: 143 | C114: CINTA TIPO RAZO TEJIDA 5CM CONTRAMARCADA
A115: BOLSA PLASTICA POLIP ADH TRANSP. 30CMX40XM CAL 1.5 | B115: 144 | C115: BOLSA PLAST PLIP ADH TRANSP30CMX40CAL1.5
A116: CIERRE GRAL DISPOSICION | B116: 195 | C116: CIERRE GRAL DISPOSICION
A117: CUELLO GRAL DISPOSICION | B117: 196 | C117: CUELLO GRAL DISPOSICION
...

Sheet Lotes Insumos
A1: Lote Matt | B1: Lote Ura | C1: Item Matt | D1: Item URA
A2: 202511280000075 | B2: 202603250000001 | C2: 94900 | D2: 2088
A3: 202601140000104 | B3: 202603250000002 | C3: 94764 | D3: 2053
A4: 202601270000007 | B4: 202603250000003 | C4: 95942 | D4: 2237
A5: 202602090000020 | B5: 202603250000004 | C5: 96461 | D5: 2257
A6: 202601140000072 | B6: 202603250000005 | C6: 92381 | D6: 1636
A7: 202601270000010 | B7: 202603250000006 | C7: 95221 | D7: 2128
A8: 202602090000012 | B8: 202603250000007 | C8: 96456 | D8: 2253
A9: 202602090000013 | B9: 202603250000008 | C9: 96456 | D9: 2253
A10: 202602240000024 | B10: 202603250000009 | C10: 93719 | D10: 1859
A11: 202601270000006 | B11: 202603250000010 | C11: 95940 | D11: 2235
A12: 202511110000002 | B12: 202603250000011 | C12: 92381 | D12: 1636
A13: 202511280000073 | B13: 202603250000012 | C13: 94899 | D13: 2087
... A591: 202509270000049 | B591: 202603250000435 | C591: 93024 | D591: 110

Sheet Bodegas
A1: Codigo Bodega Matt | B1: Descripcion Bodega Matt | C1: Codigo Bodega URA | D1: Descripcion Bodega URA
A2: B009 | B2: B. RECEPCION PRODUCTO TERMINADO | C2: B001 | D2: B. RECEPCION PRODUCTO TERMINADO
C3: B002 | D3: BODEGA COMPRAS GENERALES
A4: B052 | B4: BODEGA DE SEGUNDAS | C4: B003 | D4: BODEGA DE SEGUNDAS
A5: B037 | B5: B. INSUMOS | C5: B004 | D5: B. INSUMOS
A6: B011 | B6: B. MP TELAS | C6: B006 | D6: B. MP TELAS
A7: BAF01 | B7: BODEGA ACTIVOS FIJOS | C7: B007 | D7: B. ACTIVOS URA
C8: B008 | D8: BODEGA DISPOSICION FINAL
A9: B008 | B9: B. SATELITES | C9: B009 | D9: B. SATELITES
A10: B014 | B10: B. TELA IMPORTADA | C10: B010 | D10: B. TELA IMPORTADA
A11: B022 | B11: B. INV X FACTURAR A PROVEEDORES | C11: B011 | D11: B. INV X FACTURAR A PROVEEDORES
A12: B027 | B12: B. CELULAS DESARROLLO | C12: B012 | D12: B. CELULAS DESARROLLO
A13: B031 | B13: B. BORDADO (IDP) | C13: B013 | D13: B. BORDADO (IDP)
A14: B032 | B14: B. TERMINACION (IDP) | C14: B014 | D14: B. TERMINACION (IDP)
A15: B015 | B15: B. ESTAMPACION EXTERNA (IDP) | C15: B015 | D15: B. ESTAMPACION EXTERNA (IDP)
A16: B035 | B16: B. LIBERACION PARCIAL | C16: B016 | D16: B. LIBERACION PARCIAL
A17: B036 | B17: B. DEVOLUCIONES TELA | C17: B017 | D17: B. DEVOLUCIONES TELA
A18: B038 | B18: B. INSUMOS PRODUCCION SIN COSTO | C18: B018 | D18: B. INSUMOS PRODUCCION SIN COSTO
A19: B039 | B19: B. LOGISTICA DE ESTAMPACION | C19: B019 | D19: B. LOGISTICA DE ESTAMPACION
A20: B042 | B20: B. LOGISTICA CONFECC | C20: B020 | D20: B. LOGISTICA DE CONFECCION
... A31: B033 | B31: B. ESTAMPACION EXTERNA (IDP) | C31: B031 | D31: B. ESTAMPACION EXTERNA (IDP)

Sheet Ruta Generica URA
A1: Operación | B1: Descripción | C1: Item Serv/CT | F1: DESCRIPCIÓN DE LA OPERACIÓN | G1: TIPO DE OPERACIÓN(0=interna,1=Externa) | H1: ÍTEM DEL SERVICIO | I1: TARIFA EXTERNA | J1: CENTRO DE TRABAJO(solo aplica para operaciones internas) | K1: CANTIDAD BASE (Si es una operación externa =1) | L1: N° HORAS DE EJECCIÓN(solo aplica para operaciones internas)
A2: 1 | B2: CORTE INTERNO | C2: CT002 | F2: ESTAMPACION EXTERNA | G2: 1 | H2: 3 | I2: 1 | K2: 1 | L2: 0
A3: 2 | B3: CORTE EXTERNO | C3: 193 | F3: LAVANDERIA | G3: 1 | H3: 4 | I3: 1 | K3: 1 | L3: 0
A4: 4 | B4: SESGO | C4: 185 | F4: SESGO | G4: 1 | H4: 6 | I4: 1 | K4: 1 | L4: 0
A5: 5 | B5: FUSIONADO | C5: 190 | F5: BORDADO (TRENZADO) | G5: 1 | H5: 8 | I5: 1 | K5: 1 | L5: 0
A6: 6 | B6: ESTAMPACION EXTERNA | C6: 183 | F6: MANUALIDADES (APLIQUES) | G6: 1 | H6: 9 | I6: 1 | K6: 1 | L6: 0
A7: 7 | B7: ESTAMPACION INTERNA | C7: CT003 | F7: CONFECCION EXTERNA 2 | G7: 1 | H7: 11 | I7: 1 | K7: 1 | L7: 0
A8: 8 | B8: LAVANDERIA | C8: 184 | F8: FUSIONADO | G8: 1 | H8: 19 | I8: 1 | K8: 1 | L8: 0
A9: 9 | B9: BORDADO (TRENZADO) | C9: 187 | F9: PLISADO | G9: 1 | H9: 26134 | I9: 1 | K9: 1 | L9: 0
A10: 10 | B10: CONFECCION INTERNA | C10: CT004 | F10: REPUJADO | G10: 1 | H10: 45506 | I10: 1 | K10: 1 | L10: 0
A11: 11 | B11: CONFECCION EXTERNA | C11: 189 | F11: ESTAMPACION INTERNA | G11: 0 | H11: 0 | I11: 0 | J11: CT003 | K11: 54718 | L11: 303
A12: 12 | B12: PLISADO | C12: 191 | F12: CONFECCION INTERNA | G12: 0 | H12: 0 | I12: 0 | J12: CT002 | K12: 28824 | L12: 5044
A13: 13 | B13: MANUALIDADES (APLIQUES) | C13: 188 | F13: CONFECCION EXTERNA | G13: 1 | H13: 11 | I13: 1 | K13: 1 | L13: 0
A14: 14 | B14: REPUJADO | C14: 192 | F14: CORTE EXTERNO | G14: 1 | H14: 10 | I14: 1 | K14: 1 | L14: 0
A15: 15 | B15: OPERACIONES | C15: CT001 | F15: OPERACIONES | G15: 0 | H15: 0 | I15: 0 | J15: CT010 | K15: 134583 | L15: 192
F16: DISEÑO | G16: 0 | H16: 0 | I16: 0 | J16: CT009 | K16: 137087 | L16: 192
F17: CORTE INTERNO | G17: 0 | H17: 0 | I17: 0 | J17: CT004 | K17: 113490 | L17: 268

Sheet Items Hilos
A1: Item Mattelsa | B1: Item URA | C1: Descripcion
A2: 22510 | B2: 2369 | C2: PERMA CORE PET SPUN 100% T-24 2743 MT
A3: 22514 | B3: 2370 | C3: ALG APT 100% CALIBRE 60-5000 MTS
A4: 88845 | B4: 2371 | C4: HILO EPIC ECV120T24 2500 MT

Sheet Extensiones Hilos
A1: Codigo Ext Matt | B1: Descripcion Extension | C1: Codigo Ext URA
A2: 07DVA | B2: CAFE | C2: 07DVA
A3: 22DVA | B3: CAFÉ OSCURO 19-P | C3: 22DVA
A4: 23442 | B4: ROJO 6-D | C4: 23442
A5: 32718 | B5: AZUL 10-G | C5: 32718
A6: 43656 | B6: ROSADO 8-B | C6: 43656
A7: 52FVA | B7: ROSA PASTEL 5-G | C7: 52FVA
A8: 6985 | B8: AZUL 12-H | C8: 6985
A9: C1158 | B9: AMARILLO 1-J | C9: C1158
A10: C3256 | B10: CORAL 4-C | C10: C3256
A11: C3944 | B11: MARRON 7-F | C11: C3944
A12: C3974 | B12: VINO 5-P | C12: C3974
A13: C7389 | B13: AZUL 10-L | C13: C7389
A14: C7588 | B14: AZUL OSCURO 22-L | C14: C7588
A15: C8106 | B15: GRIS 17-J | C15: C8106
A16: C8510 | B16: GRIS 15-I | C16: C8510
A17: C8680 | B17: CAFÉ 19-R | C17: C8680
A18: C9345 | B18: AZUL 10-B | C18: C9345
A19: C9353 | B19: GRIS 20-E | C19: C9353
A20: C9368 | B20: GRIS 15-F | C20: C9368
A21: 02KVA | B21: VERDE 14-S | C21: 02KVA
A22: 41462 | B22: BLANCO 1-A | C22: 41462
A23: 5401 | B23: NEGRO 17-F | C23: 5401
A24: 5402 | B24: MARFIL 1-C | C24: 5402
A25: C1700 | B25: BLANCO 23-E | C25: C1700
A26: C2712 | B26: BEIGE 1-A | C26: C2712
A27: C8125 | B27: BEIGE 2-B | C27: C8125
A28: C9700 | B28: NEGRO 23-C | C28: C9700
A29: DIMAX40 | B29: DIMAX 40 COATS | C29: DIMAX40
A30: DIMAX60 | B30: DIMAX 60 COATS | C30: DIMAX60

Sheet Lotes Hilos
A1: Lote Matt | B1: Lote Ura | C1: Item Matt | D1: Item URA | E1: Extension Matt
A2: 207408 | B2: 1 | C2: 22510 | D2: 2369
A3: 207409 | B3: 2 | C3: 22510 | D3: 2369
A4: 207410 | B4: 3 | C4: 22510 | D4: 2369
A5: 207411 | B5: 4 | C5: 22510 | D5: 2369
A6: 207412 | B6: 5 | C6: 22510 | D6: 2369
A7: 207413 | B7: 6 | C7: 22510 | D7: 2369
A8: 207414 | B8: 7 | C8: 22510 | D8: 2369
A9: 207415 | B9: 8 | C9: 22510 | D9: 2369
A10: 207416 | B10: 9 | C10: 22510 | D10: 2369
A11: 207417 | B11: 10 | C11: 22510 | D11: 2369
A12: 207418 | B12: 11 | C12: 22510 | D12: 2369
A13: 207419 | B13: 12 | C13: 22510 | D13: 2369
... A1114: 206842 | B1114: 1113 | C1114: 88845 | D1114: 2371
A1115: 204853 | B1115: 1114 | C1115: 88845 | D1115: =+_xlfn.XLOOKUP(C1115,'Items Hilos'!$A:$A,'Items Hilos'!$B:$B) -> 2371 | E1115: C1158
A1116: 204854 | B1116: 1115 | C1116: 88845 | D1116: =+_xlfn.XLOOKUP(C1116,'Items Hilos'!$A:$A,'Items Hilos'!$B:$B) -> 2371 | E1116: C1158
A1117: 204855 | B1117: 1116 | C1117: 88845 | D1117: =+_xlfn.XLOOKUP(C1117,'Items Hilos'!$A:$A,'Items Hilos'!$B:$B) -> 2371 | E1117: C1158
A1118: 204847 | B1118: 1117 | C1118: 88845 | D1118: =+_xlfn.XLOOKUP(C1118,'Items Hilos'!$A:$A,'Items Hilos'!$B:$B) -> 2371 | E1118: C1158
A1119: 204848 | B1119: 1118 | C1119: 88845 | D1119: =+_xlfn.XLOOKUP(C1119,'Items Hilos'!$A:$A,'Items Hilos'!$B:$B) -> 2371 | E1119: C1158
A1120: 204849 | B1120: 1119 | C1120: 88845 | D1120: =+_xlfn.XLOOKUP(C1120,'Items Hilos'!$A:$A,'Items Hilos'!$B:$B) -> 2371 | E1120: C1158
A1121: 204850 | B1121: 1120 | C1121: 88845 | D1121: =+_xlfn.XLOOKUP(C1121,'Items Hilos'!$A:$A,'Items Hilos'!$B:$B) -> 2371 | E1121: C1158
A1122: 204851 | B1122: 1121 | C1122: 88845 | D1122: =+_xlfn.XLOOKUP(C1122,'Items Hilos'!$A:$A,'Items Hilos'!$B:$B) -> 2371 | E1122: C1158
A1123: 204852 | B1123: 1122 | C1123: 88845 | D1123: =+_xlfn.XLOOKUP(C1123,'Items Hilos'!$A:$A,'Items Hilos'!$B:$B) -> 2371 | E1123: C1158
A1124: 204841 | B1124: 1123 | C1124: 88845 | D1124: =+_xlfn.XLOOKUP(C1124,'Items Hilos'!$A:$A,'Items Hilos'!$B:$B) -> 2371 | E1124: C1158
A1125: 204842 | B1125: 1124 | C1125: 88845 | D1125: =+_xlfn.XLOOKUP(C1125,'Items Hilos'!$A:$A,'Items Hilos'!$B:$B) -> 2371 | E1125: C1158
A1126: 204843 | B1126: 1125 | C1126: 88845 | D1126: =+_xlfn.XLOOKUP(C1126,'Items Hilos'!$A:$A,'Items Hilos'!$B:$B) -> 2371 | E1126: C1158
... A1903: 208225 | B1903: 1902 | C1903: 88845 | D1903: =+_xlfn.XLOOKUP(C1903,'Items Hilos'!$A:$A,'Items Hilos'!$B:$B) -> 2371 | E1903: C3944

Sheet Items Tintas
A1: Item Mattelsa | B1: Item URA | C1: Descripcion
A2: 18569 | B2: 2372 | C2: 18569 - CORROSION
A3: 18570 | B3: 2373 | C3: 18570-TEXTIL
A4: 18571 | B4: 2374 | C4: 18571-PLASTISOL
A5: 18573 | B5: 2375 | C5: 18573-PLASTISOL PUFF
A6: 18575 | B6: 2376 | C6: 18575-PLASTISOL HD

Sheet Extensiones Tintas
A1: Codigo Ext Matt | B1: Descripcion Extension | C1: Codigo Ext URA
A2: 1393 | B2: 1393P06 PIGMENTO AZUL TEXTIL | C2: 1393
A3: 1394 | B3: 1394P06 PIGMENTO VERDE TEXTIL | C3: 1394
A4: 3D MIX BASE | B4: TXP 3D MIX BASE | C4: 3D MIX BASE
A5: BA65018 | B5: BA65018P01 ACUAPRINT 120EF NEGROPROCES | C5: BA65018
A6: BLANC 670 | B6: BLANC 670 INNOVAQUIMICOS | C6: BLANC 670
A7: FIBERBOND TXP | B7: TXP FIBERBOND | C7: FIBERBOND TXP
A8: NL0102 | B8: NL0102P01 AMARILLO SPCTE ELONGABLE NF | C8: NL0102
A9: NL0103 | B9: NL0103P01 AMARILLO OROSC ELONGABLE NF | C9: NL0103
A10: NL0201 | B10: NL0201P01 AZUL SPCTE ELONGABLE NF | C10: NL0201
A11: NL0208 | B11: NL0208P01 AZUL NAVY SPCTE ELONGABLE NF | C11: NL0208
A12: NL0212 | B12: NL0212P01 AZUL FLUOR SPCTE ELONGABLE NF | C12: NL0212
A13: NL0602 | B13: NL0602 MAGENTA OSCURO | C13: NL0602
A14: NL0703 | B14: NL0703P01 NARANJA FLUORSC ELONGABLE NF | C14: NL0703
A15: NL0901 | B15: NL0901P01 ROJO SPCTE ELONGABLE NF | C15: NL0901
... A86: TXP SHINY LINER 100 | B86: TXP SHINY LINER 100 | C86: TXP SHINY LINER 100

Sheet Lotes Tintas
A1: Lote Matt | B1: Lote Ura | C1: Item Matt | D1: Item URA
A2: 68678 | B2: 1 | C2: 18570 | D2: 2373
A3: 68769 | B3: 2 | C3: 18570 | D3: 2373
A4: 68682 | B4: 3 | C4: 18570 | D4: 2373
A5: 68712 | B5: 4 | C5: 18570 | D5: 2373
A6: 68814 | B6: 5 | C6: 18570 | D6: 2373
A7: 68233 | B7: 6 | C7: 18570 | D7: 2373
A8: 68681 | B8: 7 | C8: 18570 | D8: 2373
A9: 68799 | B9: 8 | C9: 18570 | D9: 2373
A10: 66441 | B10: 9 | C10: 18570 | D10: 2373
A11: 68763 | B11: 10 | C11: 18571 | D11: 2374
A12: 68762 | B12: 11 | C12: 18571 | D12: 2374
A13: 68899 | B13: 12 | C13: 18571 | D13: 2374
... A44: 68565 | B44: 43 | C44: 68565 | D44: 2376

Sheet Items B. Servicio
A1: Item Mattelsa | B1: Item URA | C1: Descripcion
A2: 93666 | B2: 2445 | C2: CAFE NESPRESSO
A3: 92357 | B3: 2446 | C3: TORTILLA GRANDE X10 UND
A4: 23612 | B4: 2447 | C4: PAPAS LIMA LIMON X25GR MONTE ROJO
A5: 29838 | B5: 2448 | C5: COMINO MOLIDO
A6: 52085 | B6: 2449 | C6: FECULA DE YUCA
A7: 52155 | B7: 2450 | C7: LEVADURA NUTRICIONAL
A8: 52158 | B8: 2451 | C8: MAIZ TOSTADO
A9: 52159 | B9: 2452 | C9: MANI TOSTADO
A10: 52160 | B10: 2453 | C10: MARAÑON NATURAL
A11: 52231 | B11: 2454 | C11: BEBIDA SODA BOTELLA
A12: 52296 | B12: 2455 | C12: CHORIVEGANO PAQUETE X 8 UND
A13: 72129 | B13: 2456 | C13: SAL MARINA REFISAL X 800 GR
... A201: 97391 | B201: 2644 | C201: PIGMENTO RESINA HL 101

Sheet Extensiones B. Servicio
A1: Codigo Ext Matt | B1: Descripcion Extension | C1: Codigo Ext URA
A2: VANIGLIA | B2: VANIGLIA | C2: VANIGLIA
A3: VOLLUTO | B3: VOLLUTO | C3: VOLLUTO
A4: FRUTOS AMARILLOS | B4: FRUTOS AMARILLOS | C4: FRUTOS AMARILLOS
A5: CARAMELO | B5: CARAMELO | C5: CARAMELO
A6: COLOMBIA | B6: COLOMBIA | C6: COLOMBIA
A7: EMULSION UNIFILM | B7: EMULSION UNIFILM 3D NEW | C7: EMULSION UNIFILM
A8: BLANCO | B8: BLANCO | C8: BLANCO
A9: SPOT 60W REST PRODU | B9: BOMBILLO 60W SPOT RESTAURANTE PRODUCCION | C9: SPOT 60W REST PRODU
A10: ROJO MADERA | B10: ROJO MADERA | C10: ROJO MADERA
A11: AMARILLO | B11: AMARILLO | C11: AMARILLO
A12: TRAFICO AMARILLO COR | B12: TRAFICO AMARRILLO CORONA | C12: TRAFICO AMARILLO COR
... A272: TALLA 45 | B272: TALLA 45 | C272: TALLA 45
A273: CRC 556 LUBRICANTE | C273: CRC 556 LUBRICANTE

Sheet Lotes B. Servicio
A1: Lote Matt | B1: Lote Ura | C1: Item Matt | D1: Item URA | E1: Extension
A2: 202602260000026 | B2: 202603280000001 | C2: 70676 | D2: 2585 | E2: 4 LITROS
A3: 202603250000018 | B3: 202603280000002 | C3: 70676 | D3: 2585 | E3: 4 LITROS
A4: 202601260000014 | B4: 202603280000003 | C4: 70676 | D4: 2585 | E4: 4 LITROS
A5: 202603240000015 | B5: 202603280000004 | C5: 70676 | D5: 2585 | E5: 20 LT
A6: 202602260000024 | B6: 202603280000005 | C6: 70676 | D6: 2585 | E6: 20 LT
A7: 202601260000011 | B7: 202603280000006 | C7: 70676 | D7: 2585 | E7: 20 LT
A8: 202603250000017 | B8: 202603280000007 | C8: 70675 | D8: 2595 | E8: 20 LT
A9: 202602260000025 | B9: 202603280000008 | C9: 70675 | D9: 2595 | E9: 20 LT
A10: 202601260000013 | B10: 202603280000009 | C10: 70675 | D10: 2595 | E10: 20 LT
A11: 202603250000020 | B11: 202603280000010 | C11: 70674 | D11: 2594 | E11: 20 LT
A12: 202602260000028 | B12: 202603280000011 | C12: 70674 | D12: 2594 | E12: 20 LT
A13: 202602260000010 | B13: 202603280000012 | C13: 53779 | D13: 2603 | E13: ROJA 26*36 PAQX100
... A375: 202509260000055 | B375: 202603280000374 | C375: 54933 | D375: 2643 | E375: PETO BLANCO
A376: 202508200000038 | B376: 202603280000375 | C376: 71291 | D376: 706
A377: 202510080000036 | B377: 202603280000376 | C377: 71291 | D377: 706
A378: 202601260000015 | B378: 202603280000380 | C378: 74450 | D378: 2597 | E378: CUÑETE X 20 KG
A379: 202602260000027 | B379: 202603280000381 | C379: 74450 | D379: 2597 | E379: CUÑETE X 20 KG
A380: 202603250000019 | B380: 202603280000382 | C380: 74450 | D380: 2597 | E380: CUÑETE X 20 KG
A381: 202612600000016 | B381: 202603280000383 | C381: 74451 | D381: 2598 | E381: CUÑETE X 20 KG
A382: 202603250000023 | B382: 202603280000384 | C382: 74451 | D382: 2598 | E382: CUÑETE X 20 KG
A383: 202510230000017 | B383: 202603280000401 | C383: 82490 | D383: 2528 | E383: RAPCOR 90° 6MM X 1/8 NPT
A384: 202505270000048 | B384: 202603280000386 | C384: 82490 | D384: 2528 | E384: RAPCOR 90° 6MM X 1/8 NPT
A385: 202506230000005 | B385: 202603280000387 | C385: 82502 | D385: 2534 | E385: CONTACTO DÚPLEX
A386: 202511110000057 | B386: 202603280000388 | C386: 82490 | D386: 2528 | E386: RAPCOR 90° 6MM A 1/4
A387: 202602110000020 | B387: 202603280000389 | C387: 54927 | D387: 2613 | E387: CUÑETE X 20 KG
A388: 202603120000083 | B388: 202603280000390 | C388: 54927 | D388: 2613 | E388: CUÑETE X 20 KG
A389: 202603130000004 | B389: 202603280000391 | C389: 54974 | D389: 2624 | E389: BIO1 CUÑETE X 20
... A401: 202603280000004 | B401: 202603290000005 | C401: 97391 | D401: 2644 | E401: PIGMENTO RESINA HL 1-NA

Sheet Items PT
A1: Item Mattelsa | B1: Item URA | C1: Descripcion | D1: Tipo de Inventario
A2: 89453 | B2: 1 | C2: CAMISETA(1424A1783)1MAD | D2: PTC
A3: 89454 | B3: 2 | C3: BUZO H (1424A1783) 2MAD | D3: PTC
A4: 90862 | B4: 3 | C4: CAMISETA (225)39MAD | D4: PTC
A5: 90863 | B5: 4 | C5: BUZO(225)5MAD | D5: PTC
A6: 90864 | B6: 5 | C6: JOGGER(225)4MAD | D6: PTC
A7: 90932 | B7: 6 | C7: TOTEBAG(225) | D7: PTC
A8: 91653 | B8: 9 | C8: CAMISETA RYL_MM2 | D8: PTC
A9: 91967 | B9: 10 | C9: CAMISETA RYL_BM | D9: PTC
A10: 0000011 | B10: 11 | C10: PROTOTIPOS | D10: PTC
A11: 92663 | B11: 14 | C11: CAMISETA URA_DTUF(LOGO URA) | D11: PTC
A12: 92664 | B12: 15 | C12: CAMISETA URA_DTUF(MURAL URA) | D12: PTC
A13: 92665 | B13: 16 | C13: CAMISETA URA_DTUF(LOGO URA) | D13: PTC
A14: 92666 | B14: 17 | C14: CAMISETA URA_DTUF(MURAL URA) | D14: PTC
A15: 91996 | B15: 18 | C15: BUZO RYL_RMN(HOODIE) | D15: PTC
A16: 91997 | B16: 19 | C16: BUZO RYL_RMN(PULLOVER) | D16: PTC
A17: 91998 | B17: 20 | C17: CAMISETA RYL_RMN(CAMISETA) | D17: PTP
A18: 94320 | B18: 26 | C18: CAMISETA PTS_FST25(M) | D18: PTC
A19: 92410 | B19: 134 | C19: SHORT CLM_LVA(MORMORIO-N) | D19: PTC
A20: 92411 | B20: 135 | C20: JOGGER CLM_LOSC(SPETTRALE-R) | D20: PTC
A21: 92412 | B21: 136 | C21: BUZO CLM_LOSC(DISTRUTTO-N) | D21: PTC
A22: 92413 | B22: 137 | C22: BUZO CLM_LOSC(DISTRUTTO-R) | D22: PTC
... A45: 93737 | B45: 207 | C45: BUZO CLM_LVA(ABISSALE-N) | D45: PTP
A46: BUZO CLM_LVA(ABISSALE-R) | B46: 208 | C46: BUZO CLM_LVA(ABISSALE-R) | D46: PTC
A47: 93635 | B47: 209 | C47: CAMISETA CLM_LVA(ADERIRE-G) | D47: PTS
A48: 93634 | B48: 210 | C48: CAMISETA CLM_LVA(ADERIRE-M) | D48: PTS
A49: 93633 | B49: 211 | C49: CAMISETA CLM_LVA(ADERIRE-N) | D49: PTS
A50: 94509 | B50: 212 | C50: CHAQUETA CLM_LVO(APOSTOLO-G) | D50: PTP
A51: 94501 | B51: 213 | C51: CHAQUETA CLM_LVO(APOSTOLO-N) | D51: PTP
A52: 94510 | B52: 214 | C52: JOGGER CLM_LVO(BAGLIORI-G) | D52: PTP
A53: 94503 | B53: 215 | C53: JOGGER CLM_LVO(BAGLIORI-N) | D53: PTP
A54: 94526 | B54: 216 | C54: CAMISETA CLM_LVS(CHERUBINO-M) | D54: PTP
A55: 94525 | B55: 217 | C55: CAMISETA CLM_LVS(CHERUBINO-N) | D55: PTP
A56: 94527 | B56: 218 | C56: CAMISETA CLM_LVS(CHERUBINO-R) | D56: PTP
A57: CAMISETA CLM_LVA(EVOLVERE-G) | B57: 219 | C57: CAMISETA CLM_LVA(EVOLVERE-G) | D57: PTC
A58: CAMISETA CLM_LVA(EVOLVERE-M) | B58: 220 | C58: CAMISETA CLM_LVA(EVOLVERE-M) | D58: PTC
A59: CAMISETA CLM_LVA(EVOLVERE-N) | B59: 221 | C59: CAMISETA CLM_LVA(EVOLVERE-N) | D59: PTC
A60: 94673 | B60: 222 | C60: CAMISETA CLM_LVS(LUSINGA-G) | D60: PTP
A61: 94672 | B61: 223 | C61: CAMISETA CLM_LVS(LUSINGA-M) | D61: PTP
A62: 94671 | B62: 224 | C62: CAMISETA CLM_LVS(LUSINGA-N) | D62: PTP
...

Sheet Planes
A1: Descripción plan Mattelsa | B1: Plan Mattelsa | C1: Plan URA | D1: Descripcion plan URA
A2: GENERO | B2: 1 | C2: 1 | D2: GENERO
A3: CATEGORIA | B3: 2 | C3: 2 | D3: CATEGORIA
A4: CLIENTE URA | B4: 45 | C4: 3 | D4: CLIENTE
A5: MARCA | B5: 3 | C5: 4 | D5: MARCA
A6: COLECCIÓN | B6: 7 | C6: 5 | D6: COLECCIÓN
A7: COLECCION AJUSTADA | B7: 16 | C7: 6 | D7: COLECCIÓN AJUSTADA
A8: COLECCION ESPECIAL | B8: 24 | C8: 7 | D8: COLECCION ESPECIAL
A9: CANTIDAD | B9: 8 | C9: 8 | D9: LOTE
A10: CELULA | B10: 17 | C10: 9 | D10: CELULA
A11: CANCELADO | B11: 30 | C11: 11 | D11: CANCELADO
A12: PROYECTO URA | B12: 46 | C12: 12 | D12: PROYECTO
A13: COMPLEJIDAD | B13: 44 | C13: 14 | D13: COMPLEJIDAD
... A19: MERCADO | B19: 15 | C19: 26 | D19: MERCADO

Sheet Mayores
A1: Descripción plan Mattelsa | B1: Descripción mayor Mattelsa | C1: Plan Mattelsa | D1: Mayor Mattelsa | E1: Plan URA | F1: Mayor URA | G1: Descripcion plan URA | H1: Descripción mayor URA
A2: CANCELADO | B2: NO | C2: 30 | D2: 02 | E2: 11 | F2: 2 | G2: CANCELADO | H2: NO
A3: CANCELADO | B3: SI | C3: 30 | D3: 01 | E3: 11 | F3: 1 | G3: CANCELADO | H3: SI
A4: CANTIDAD | B4: 1 | C4: 8 | D4: 1 | E4: 8 | F4: 1 | G4: LOTE | H4: 1
A5: CANTIDAD | B5: 2 | C5: 8 | D5: 2 | E5: 8 | F5: 2 | G5: LOTE | H5: 2
A6: CANTIDAD | B6: 3 | C6: 8 | D6: 3 | E6: 8 | F6: 3 | G6: LOTE | H6: 3
A7: CANTIDAD | B7: 4 | C7: 8 | D7: 4 | E7: 8 | F7: 4 | G7: LOTE | H7: 4
A8: CANTIDAD | B8: 5 | C8: 8 | D8: 5 | E8: 8 | F8: 5 | G8: LOTE | H8: 5
A9: CANTIDAD | B9: 6 | C9: 8 | D9: 6 | E9: 8 | F9: 6 | G9: LOTE | H9: 6
A10: CANTIDAD | B10: 7 | C10: 8 | D10: 7 | E10: 8 | F10: 7 | G10: LOTE | H10: 7
A11: CANTIDAD | B11: 8 | C11: 8 | D11: 8 | E11: 8 | F11: 8 | G11: LOTE | H11: 8
A12: CANTIDAD | B12: 9 | C12: 8 | D12: 9 | E12: 8 | F12: 9 | G12: LOTE | H12: 9
A13: CANTIDAD | B13: 10 | C13: 8 | D13: 10 | E13: 8 | F13: 10 | G13: LOTE | H13: 10
... A3291: TIPO TEJIDO | B3291: PUNTO PESADO | C3291: 41 | D3291: 04 | E3291: 25 | F3291: 4 | G3291: TIPO TEJIDO | H3291: PUNTO PESADO

Sheet OPs
A1: OP Matt | B1: Item PT Matt | C1: OP Ura | D1: Item PT Ura
A2: 37735 | B2: 90355 | C2: 2 | D2: 2646
A3: 37787 | B3: 90357 | C3: 3 | D3: 2647
A4: 37981 | B4: 90409 | C4: 4 | D4: 2648
A5: 38210 | B5: 91413 | C5: 5 | D5: 2654
A6: 38231 | B6: 87520 | C6: 6 | D6: 2645
A7: 38232 | B7: 91412 | C7: 7 | D7: 2653
A8: 38242 | B8: 91515 | C8: 8 | D8: 2659
A9: 38289 | B9: 90698 | C9: 9 | D9: 2650
A10: 38303 | B10: 91308 | C10: 10 | D10: 2652
A11: 38327 | B11: 91513 | C11: 11 | D11: 2658
A12: 38360 | B12: 91479 | C12: 12 | D12: 2655
A13: 38368 | B13: 91512 | C13: 13 | D13: 2657
... A301: 39195 | B301: 95965 | C301: 301 | D301: 3279

Sheet Ordenes de Compra
A1: OC Matt | B1: OC URA | C1: Proveedor | D1: Tipo de Inventario
A2: OC-00044354 | B2: OC-00000055 | C2: MANUFACTURAS ELIOT S.A.S. | D2: MPT
A3: OCI-00000243 | B3: OCI-00000002 | C3: SAPPHIRE FIBRES LIMITED | D3: MPT
A4: OC-00044362 | B4: OC-00000056 | C4: FABRICATO S.A. EN ACUERDO DE RESTRUCTURACION | D4: MPT
A5: OC-00044363 | B5: OC-00000057 | C5: PROTELA S.A | D5: MPT
A6: OC-00044365 | B6: OC-00000058 | C6: ARTEXTIL SAS | D6: MPT
A7: OCI-00000248 | B7: OCI-00000003 | C7: CREDITEX S.A.A | D7: MPT
A8: OC-00044369 | B8: OC-00000059 | C8: SUTEX S.A.S | D8: MPT
A9: OCI-00000249 | B9: OCI-00000005 | C9: PRECOTEX SAC | D9: MPT
A10: OCI-00000249 | B10: OCI-00000004 | C10: PRECOTEX SAC | D10: MPT
A11: OCI-00000249 | B11: OCI-00000001 | C11: PRECOTEX SAC | D11: MPT
A12: OC-00044370 | B12: OC-00000060 | C12: FABRICATO S.A. EN ACUERDO DE RESTRUCTURACION | D12: MPT
... A281: OC-00143316 | B281: OC-00000122 | C281: TERMIMODA S.A | D281: Producto en Proceso
